<?xml version="1.0" ?>
<!-- =================================================================================== -->
<!-- |    This document was autogenerated by xacro from src/dex_bot/urdf/dex_bot.xacro | -->
<!-- |    EDITING THIS FILE BY HAND IS NOT RECOMMENDED                                 | -->
<!-- =================================================================================== -->
<robot name="dex_bot">
  <!-- <material name="${body_color}">
  <color rgba="0.700 0.700 0.700 1.000"/>
</material> -->
  <!-- <gazebo>
  <plugin name="control" filename="libgazebo_ros2_control.so"/>
</gazebo> -->
  <link name="arm_L0_1">
    <inertial>
      <origin rpy="0 0 0" xyz="-0.0005084775591485124 0.5246904244223437 0.13216732658890662"/>
      <mass value="48.0088488740698"/>
      <inertia ixx="1.070844" ixy="0.004532" ixz="0.001817" iyy="0.581071" iyz="0.168709" izz="1.042479"/>
    </inertial>
    <visual>
      <origin rpy="0 0 0" xyz="-0.725 1.048 -0.75"/>
      <geometry>
        <mesh filename="meshes/arm_L0_1.stl" scale="0.001 0.001 0.001"/>
      </geometry>
      <material name="silver"/>
    </visual>
    <collision>
      <origin rpy="0 0 0" xyz="-0.725 1.048 -0.75"/>
      <geometry>
        <mesh filename="meshes/arm_L0_1.stl" scale="0.001 0.001 0.001"/>
      </geometry>
    </collision>
  </link>
  <link name="arm_L1_1">
    <inertial>
      <origin rpy="0 0 0" xyz="-0.03470375236635259 3.9460788037182226e-07 0.2186631315117692"/>
      <mass value="39.40025124273763"/>
      <inertia ixx="0.695419" ixy="-1e-06" ixz="0.048341" iyy="0.778283" iyz="9e-06" izz="0.365307"/>
    </inertial>
    <visual>
      <origin rpy="0 0 0" xyz="-0.725 0.423315 -0.985"/>
      <geometry>
        <mesh filename="meshes/arm_L1_1.stl" scale="0.001 0.001 0.001"/>
      </geometry>
      <material name="silver"/>
    </visual>
    <collision>
      <origin rpy="0 0 0" xyz="-0.725 0.423315 -0.985"/>
      <geometry>
        <mesh filename="meshes/arm_L1_1.stl" scale="0.001 0.001 0.001"/>
      </geometry>
    </collision>
  </link>
  <link name="arm_L2_1">
    <inertial>
      <origin rpy="0 0 0" xyz="0.08686964865130697 -0.00036228003561100675 0.2760296807586029"/>
      <mass value="29.782191113853642"/>
      <inertia ixx="2.171052" ixy="-0.000666" ixz="-0.10942" iyy="2.151048" iyz="-4.4e-05" izz="0.11547"/>
    </inertial>
    <visual>
      <origin rpy="0 0 0" xyz="-0.798 0.423315 -1.32"/>
      <geometry>
        <mesh filename="meshes/arm_L2_1.stl" scale="0.001 0.001 0.001"/>
      </geometry>
      <material name="silver"/>
    </visual>
    <collision>
      <origin rpy="0 0 0" xyz="-0.798 0.423315 -1.32"/>
      <geometry>
        <mesh filename="meshes/arm_L2_1.stl" scale="0.001 0.001 0.001"/>
      </geometry>
    </collision>
  </link>
  <link name="arm_L3_1">
    <inertial>
      <origin rpy="0 0 0" xyz="-0.11216609330790506 0.008862440197980992 0.00026958674010657546"/>
      <mass value="16.73058890439377"/>
      <inertia ixx="0.116337" ixy="0.001898" ixz="0.000283" iyy="0.108254" iyz="-0.000741" izz="0.122982"/>
    </inertial>
    <visual>
      <origin rpy="0 0 0" xyz="-0.835 0.423315 -2.016131"/>
      <geometry>
        <mesh filename="meshes/arm_L3_1.stl" scale="0.001 0.001 0.001"/>
      </geometry>
      <material name="silver"/>
    </visual>
    <collision>
      <origin rpy="0 0 0" xyz="-0.835 0.423315 -2.016131"/>
      <geometry>
        <mesh filename="meshes/arm_L3_1.stl" scale="0.001 0.001 0.001"/>
      </geometry>
    </collision>
  </link>
  <link name="arm_L4_1">
    <inertial>
      <origin rpy="0 0 0" xyz="4.9945929424422e-05 0.2997392284251538 0.0001857816789221367"/>
      <mass value="11.946951298656325"/>
      <inertia ixx="0.481716" ixy="0.000901" ixz="2e-06" iyy="0.022918" iyz="-0.000102" izz="0.485145"/>
    </inertial>
    <visual>
      <origin rpy="0 0 0" xyz="-0.725 0.289915 -2.016131"/>
      <geometry>
        <mesh filename="meshes/arm_L4_1.stl" scale="0.001 0.001 0.001"/>
      </geometry>
      <material name="silver"/>
    </visual>
    <collision>
      <origin rpy="0 0 0" xyz="-0.725 0.289915 -2.016131"/>
      <geometry>
        <mesh filename="meshes/arm_L4_1.stl" scale="0.001 0.001 0.001"/>
      </geometry>
    </collision>
  </link>
  <link name="arm_L5_1">
    <inertial>
      <origin rpy="0 0 0" xyz="-0.03872088033691912 -1.2710397158832709e-05 -0.009061695493699062"/>
      <mass value="0.9645909322307937"/>
      <inertia ixx="0.001229" ixy="1e-06" ixz="-1e-05" iyy="0.001184" iyz="0.0" izz="0.000826"/>
    </inertial>
    <visual>
      <origin rpy="0 0 0" xyz="-0.765 -0.360085 -2.016131"/>
      <geometry>
        <mesh filename="meshes/arm_L5_1.stl" scale="0.001 0.001 0.001"/>
      </geometry>
      <material name="silver"/>
    </visual>
    <collision>
      <origin rpy="0 0 0" xyz="-0.765 -0.360085 -2.016131"/>
      <geometry>
        <mesh filename="meshes/arm_L5_1.stl" scale="0.001 0.001 0.001"/>
      </geometry>
    </collision>
  </link>

  <link name="arm_L7_2">
    <inertial>
      <origin rpy="0 0 0" xyz="-0.0038872164260756736 4.472601176031254e-06 0.02573915023374662"/>
      <mass value="0.1372353878364928"/>
      <inertia ixx="5.9e-05" ixy="0.0" ixz="1.8e-05" iyy="0.0002" iyz="-0.0" izz="0.000215"/>
    </inertial>
    <visual>
      <origin rpy="0 0 0" xyz="0.05 -1.3e-05 -0.500049"/>
      <geometry>
        <mesh filename="meshes/arm_L7_2.stl" scale="0.001 0.001 0.001"/>
      </geometry>
      <material name="silver"/>
    </visual>
    <collision>
      <origin rpy="0 0 0" xyz="0.05 -1.3e-05 -0.500049"/>
      <geometry>
        <mesh filename="meshes/arm_L7_2.stl" scale="0.001 0.001 0.001"/>
      </geometry>
    </collision>
  </link>
  <link name="arm_L8_1">
    <inertial>
      <origin rpy="0 0 0" xyz="0.0 -4.7570234809293815e-07 0.00499999743384727"/>
      <mass value="0.007704755982928965"/>
      <inertia ixx="0.0" ixy="0.0" ixz="-0.0" iyy="0.0" iyz="0.0" izz="1e-06"/>
    </inertial>
    <visual>
      <origin rpy="0 0 0" xyz="0.062 -1.8e-05 -0.537424"/>
      <geometry>
        <mesh filename="meshes/arm_L8_1.stl" scale="0.001 0.001 0.001"/>
      </geometry>
      <material name="silver"/>
    </visual>
    <!-- <collision>
    <origin xyz="0.062 -1.8e-05 -0.537424" rpy="0 0 0"/>
    <geometry>
      <mesh filename="file://$(find dex_bot)/meshes/arn_L8_1.stl" scale="0.001 0.001 0.001"/>
    </geometry>
  </collision> -->
  </link>
  <link name="arm_L6_2">
    <inertial>
      <origin rpy="0 0 0" xyz="-0.06297493798243411 -7.005067031751953e-06 0.16106219981007797"/>
      <mass value="0.5006201031909427"/>
      <inertia ixx="0.005416" ixy="0.0" ixz="0.001789" iyy="0.006256" iyz="-0.0" izz="0.000932"/>
    </inertial>
    <visual>
      <origin rpy="0 0 0" xyz="3.9e-05 9.7e-05 -0.0"/>
      <geometry>
        <mesh filename="meshes/arm_L6_3.stl" scale="0.001 0.001 0.001"/>
      </geometry>
      <material name="silver"/>
    </visual>
    <collision>
      <origin rpy="0 0 0" xyz="3.9e-05 9.7e-05 -0.0"/>
      <geometry>
        <mesh filename="meshes/arm_L6_3.stl" scale="0.001 0.001 0.001"/>
      </geometry>
    </collision>
  </link>
  <joint name="arm_joint7" type="revolute">
    <origin rpy="0 0 0" xyz="-0.049996 6e-06 0.340049"/>
    <parent link="arm_L6_2"/>
    <child link="arm_L7_2"/>
    <axis xyz="1.0 0.0 0.0"/>
    <limit effort="100" lower="-1.919862" upper="1.919862" velocity="100"/>
  </joint>
  <joint name="arm_joint8" type="revolute">
    <origin rpy="0 3.14 0" xyz="-0.012 5e-06 0.037375"/>
    <parent link="arm_L7_2"/>
    <child link="arm_L8_1"/>
    <axis xyz="0.0 0.0 1.0"/>
    <limit effort="100" lower="0.0" upper="0.0" velocity="100"/>
  </joint>

  <!-- <joint name="arm_joint0" type="fixed">
    <origin rpy="0 0 0" xyz="-0.191743 -0.398 0.175"/>
    <parent link="slide_base_1"/>
    <child link="arm_L0_1"/>
  </joint> -->
  <joint name="arm_joint1" type="revolute">
    <origin rpy="0 0 0" xyz="0.0 0.624685 0.235"/>
    <parent link="arm_L0_1"/>
    <child link="arm_L1_1"/>
    <axis xyz="0.0 -0.0 1.0"/>
    <limit effort="1000.0" lower="-3.14" upper="3.14" velocity="2.5"/>
  </joint>
  <joint name="arm_joint2" type="revolute">
    <origin rpy="0 0 0" xyz="0.073 0.0 0.335"/>
    <parent link="arm_L1_1"/>
    <child link="arm_L2_1"/>
    <axis xyz="1.0 -0.0 0.0"/>
    <limit effort="1000" lower="-3.14" upper="3.14" velocity="1000"/>
  </joint>
  <joint name="arm_joint3" type="revolute">
    <origin rpy="0 0 0" xyz="0.037 0.0 0.696131"/>
    <parent link="arm_L2_1"/>
    <child link="arm_L3_1"/>
    <axis xyz="-1.0 0.0 -0.0"/>
    <limit effort="1000" lower="-3.14" upper="3.14" velocity="1000"/>
  </joint>
  <joint name="arm_joint4" type="revolute">
    <origin rpy="0 0 0" xyz="-0.11 0.1334 0.0"/>
    <parent link="arm_L3_1"/>
    <child link="arm_L4_1"/>
    <axis xyz="-0.0 1.0 -0.0"/>
    <limit effort="1000" lower="-3.14" upper="3.14" velocity="1000"/>
  </joint>
  <joint name="arm_joint5" type="revolute">
    <origin rpy="0 0 0" xyz="0.04 0.65 0.0"/>
    <parent link="arm_L4_1"/>
    <child link="arm_L5_1"/>
    <axis xyz="-1.0 -0.0 0.0"/>
    <limit effort="1000" lower="-3.14" upper="3.14" velocity="1000"/>
  </joint>
  <joint name="arm_joint6" type="revolute">
    <origin rpy="0 3.14 0" xyz="-0.04 0.0 -0.067"/>
    <parent link="arm_L5_1"/>
    <child link="arm_L6_2"/>
    <axis xyz="-0.0 -0.0 -1.0"/>
    <limit effort="1000" lower="-3.14" upper="3.14" velocity="1000"/>
  </joint>

</robot>
